<?xml version="1.0" ?>
<!-- =================================================================================== -->
<!-- |    This document was autogenerated by xacro from ur5_iml.urdf.xacro             | -->
<!-- |    EDITING THIS FILE BY HAND IS NOT RECOMMENDED                                 | -->
<!-- =================================================================================== -->
<robot name="ur5_iml" xmlns:controller="http://playerstage.sourceforge.net/gazebo/xmlschema/#controller" xmlns:interface="http://playerstage.sourceforge.net/gazebo/xmlschema/#interface" xmlns:sensor="http://playerstage.sourceforge.net/gazebo/xmlschema/#sensor" xmlns:xacro="http://ros.org/wiki/xacro">
  <!-- MODELS -->
  <!-- robot model -->
  <material name="UR/Blue">
    <color rgba="0.0 0.0 0.8 1.0"/>
  </material>
  <material name="UR/Grey">
    <color rgba="0.7 0.7 0.7 1.0"/>
  </material>
  <!-- environment model -->
  <!-- environment model -->
  <!-- AFAG gripper model -->
  <!-- CALIBRATION -->
  <!-- robot calibration | position of the robot relative to base link -->
  <!-- Position of the (translation and rotation) -->
  <!-- composition of the robot -->
  <link name="base_link">
    <origin rpy="0 0 0" xyz="0 0 0"/>
  </link>
  <link name="afag_gripper_link">
    <origin rpy="0 0 0" xyz="0 0 0"/>
  </link>
  <!-- Robot UR5 -->
  <link name="arm_base_link">
    <visual>
      <geometry>
        <mesh filename="package://ur_description/meshes/ur5/visual/Base.dae"/>
      </geometry>
      <origin rpy="0.0 0.0 2.3561944875" xyz="0.0 0.0 0.003"/>
    </visual>
    <collision>
      <geometry>
        <mesh filename="package://ur_description/meshes/ur5/collision/Base.dae"/>
      </geometry>
      <!-- <origin rpy="0.0 0.0 0.0" xyz="0.0 0.0 -0.009159"/> -->
    </collision>
    <inertial>
      <mass value="4.0"/>
      <inertia ixx="1.0" ixy="0.0" ixz="0.0" iyy="1.0" iyz="0.0" izz="1.0"/>
    </inertial>
  </link>
  <joint name="arm_shoulder_pan_joint" type="revolute">
    <parent link="arm_base_link"/>
    <child link="arm_shoulder_link"/>
    <origin rpy="0.0 0.0 0.0" xyz="0.0 0.0 0.089159"/>
    <axis xyz="0 0 1"/>
    <limit effort="150.0" lower="-6.2831853" upper="6.2831853" velocity="3.14159265"/>
    <dynamics damping="0.4" friction="0.0"/>
  </joint>
  <link name="arm_shoulder_link">
    <visual>
      <geometry>
        <mesh filename="package://ur_description/meshes/ur5/visual/Shoulder.dae"/>
      </geometry>
    </visual>
    <collision>
      <geometry>
        <mesh filename="package://ur_description/meshes/ur5/collision/Shoulder.dae"/>
      </geometry>
      <!-- <origin rpy="0.0 0.0 0.0" xyz="0.0 0.0 -0.009159"/> -->
    </collision>
    <inertial>
      <mass value="3.7"/>
      <inertia ixx="1.0" ixy="0.0" ixz="0.0" iyy="1.0" iyz="0.0" izz="1.0"/>
      <origin rpy="0.0 0.0 0.0" xyz="0.0 0.00193 -0.02561"/>
    </inertial>
  </link>
  <joint name="arm_shoulder_lift_joint" type="revolute">
    <parent link="arm_shoulder_link"/>
    <child link="arm_upper_arm_link"/>
    <origin rpy="0.0 1.570796325 0.0" xyz="0.0 0.13585 0.0"/>
    <axis xyz="0 1 0"/>
    <limit effort="150.0" lower="-6.2831853" upper="6.2831853" velocity="3.14159265"/>
    <dynamics damping="0.4" friction="0.0"/>
  </joint>
  <link name="arm_upper_arm_link">
    <visual>
      <geometry>
        <mesh filename="package://ur_description/meshes/ur5/visual/UpperArm.dae"/>
      </geometry>
      <origin rpy="0.0 0.0 0.0" xyz="0.0 0.0 0.0"/>
    </visual>
    <collision>
      <geometry>
        <mesh filename="package://ur_description/meshes/ur5/collision/UpperArm.dae"/>
      </geometry>
      <!--       <origin rpy="0.0 0.0 0.0" xyz="0.0 0.0 0.2125"/> -->
    </collision>
    <inertial>
      <mass value="8.393"/>
      <inertia ixx="1.0" ixy="0.0" ixz="0.0" iyy="1.0" iyz="0.0" izz="1.0"/>
      <origin rpy="0.0 0.0 0.0" xyz="0.0 -0.024201 0.2125"/>
    </inertial>
  </link>
  <joint name="arm_elbow_joint" type="revolute">
    <parent link="arm_upper_arm_link"/>
    <child link="arm_forearm_link"/>
    <origin rpy="0.0 0.0 0.0" xyz="0.0 -0.1197 0.425"/>
    <axis xyz="0 1 0"/>
    <limit effort="150.0" lower="-6.2831853" upper="6.2831853" velocity="3.14159265"/>
    <dynamics damping="0.4" friction="0.0"/>
  </joint>
  <link name="arm_forearm_link">
    <visual>
      <geometry>
        <mesh filename="package://ur_description/meshes/ur5/visual/Forearm.dae"/>
      </geometry>
    </visual>
    <collision>
      <geometry>
        <mesh filename="package://ur_description/meshes/ur5/collision/Forearm.dae"/>
      </geometry>
      <!--       <origin rpy="0.0 0.0 0.0" xyz="0.0 0.0 0.196125"/> -->
    </collision>
    <inertial>
      <mass value="2.275"/>
      <origin rpy="0.0 0.0 0.0" xyz="0.0 0.0265 0.11993"/>
      <inertia ixx="1.0" ixy="0.0" ixz="0.0" iyy="1.0" iyz="0.0" izz="1.0"/>
    </inertial>
  </link>
  <joint name="arm_wrist_1_joint" type="revolute">
    <parent link="arm_forearm_link"/>
    <child link="arm_wrist_1_link"/>
    <origin rpy="0.0 1.570796325 0.0" xyz="0.0 0.0 0.39225"/>
    <axis xyz="0 1 0"/>
    <limit effort="28.0" lower="-3.14159265" upper="0.7853981625" velocity="3.14159265"/>
    <dynamics damping="0.3" friction="0.0"/>
  </joint>
  <link name="arm_wrist_1_link">
    <visual>
      <geometry>
        <mesh filename="package://ur_description/meshes/ur5/visual/Wrist1.dae"/>
      </geometry>
      <origin rpy="0.0 1.570796325 0.0" xyz="0.0 0.093 0.0"/>
    </visual>
    <collision>
      <geometry>
        <mesh filename="package://ur_description/meshes/ur5/collision/Wrist1.dae"/>
      </geometry>
      <origin rpy="0.0 1.570796325 0.0" xyz="0.0 0.093 0.0"/>
    </collision>
    <inertial>
      <mass value="1.219"/>
      <origin rpy="0.0 0.0 0.0" xyz="0.0 0.110949 0.01634"/>
      <inertia ixx="1.0" ixy="0.0" ixz="0.0" iyy="1.0" iyz="0.0" izz="1.0"/>
    </inertial>
  </link>
  <joint name="arm_wrist_2_joint" type="revolute">
    <parent link="arm_wrist_1_link"/>
    <child link="arm_wrist_2_link"/>
    <origin rpy="0.0 0.0 0.0" xyz="0.0 0.093 0.0"/>
    <axis xyz="0 0 1"/>
    <limit effort="28.0" lower="-3.14159265" upper="3.14159265" velocity="3.14159265"/>
    <dynamics damping="0.3" friction="0.0"/>
  </joint>
  <link name="arm_wrist_2_link">
    <visual>
      <geometry>
        <mesh filename="package://ur_description/meshes/ur5/visual/Wrist2.dae"/>
      </geometry>
      <origin rpy="0.0 0.0 0.0" xyz="0.0 0.0 0.09465"/>
    </visual>
    <collision>
      <geometry>
        <mesh filename="package://ur_description/meshes/ur5/collision/Wrist2.dae"/>
      </geometry>
      <origin rpy="0.0 0.0 0.0" xyz="0.0 0.0 0.09465"/>
    </collision>
    <inertial>
      <mass value="1.219"/>
      <origin rpy="0.0 0.0 0.0" xyz="0.0 0.0018 0.11099"/>
      <inertia ixx="1.0" ixy="0.0" ixz="0.0" iyy="1.0" iyz="0.0" izz="1.0"/>
    </inertial>
  </link>
  <joint name="arm_wrist_3_joint" type="revolute">
    <parent link="arm_wrist_2_link"/>
    <child link="arm_wrist_3_link"/>
    <origin rpy="0.0 0.0 0.0" xyz="0.0 0.0 0.09465"/>
    <axis xyz="0 1 0"/>
    <limit effort="28.0" lower="-3.14159265" upper="3.14159265" velocity="3.14159265"/>
    <dynamics damping="0.3" friction="0.0"/>
  </joint>
  <link name="arm_wrist_3_link">
    <visual>
      <geometry>
        <mesh filename="package://ur_description/meshes/ur5/visual/Wrist3.dae"/>
      </geometry>
    </visual>
    <collision>
      <geometry>
        <mesh filename="package://ur_description/meshes/ur5/collision/Wrist3.dae"/>
      </geometry>
    </collision>
    <inertial>
      <mass value="0.1879"/>
      <origin rpy="0.0 0.0 0.0" xyz="0.0 0.001159 0.0"/>
      <inertia ixx="1.0" ixy="0.0" ixz="0.0" iyy="1.0" iyz="0.0" izz="1.0"/>
    </inertial>
  </link>
  <joint name="arm_ee_fixed_joint" type="fixed">
    <parent link="arm_wrist_3_link"/>
    <child link="arm_ee_link"/>
    <origin rpy="0.0 0.0 1.570796325" xyz="0.0 0.0823 0.0"/>
  </joint>
  <link name="arm_ee_link"/>
  <transmission name="arm_shoulder_pan_trans">
    <type>transmission_interface/SimpleTransmission</type>
    <joint name="arm_shoulder_pan_joint"/>
    <actuator name="arm_shoulder_pan_motor">
      <hardwareInterface>EffortJointInterface</hardwareInterface>
      <mechanicalReduction>1</mechanicalReduction>
    </actuator>
  </transmission>
  <transmission name="arm_shoulder_lift_trans">
    <type>transmission_interface/SimpleTransmission</type>
    <joint name="arm_shoulder_lift_joint"/>
    <actuator name="arm_shoulder_lift_motor">
      <hardwareInterface>EffortJointInterface</hardwareInterface>
      <mechanicalReduction>1</mechanicalReduction>
    </actuator>
  </transmission>
  <transmission name="arm_elbow_trans">
    <type>transmission_interface/SimpleTransmission</type>
    <joint name="arm_elbow_joint"/>
    <actuator name="arm_elbow_motor">
      <hardwareInterface>EffortJointInterface</hardwareInterface>
      <mechanicalReduction>1</mechanicalReduction>
    </actuator>
  </transmission>
  <transmission name="arm_wrist_1_trans">
    <type>transmission_interface/SimpleTransmission</type>
    <joint name="arm_wrist_1_joint"/>
    <actuator name="arm_wrist_1_motor">
      <hardwareInterface>EffortJointInterface</hardwareInterface>
      <mechanicalReduction>1</mechanicalReduction>
    </actuator>
  </transmission>
  <transmission name="arm_wrist_2_trans">
    <type>transmission_interface/SimpleTransmission</type>
    <joint name="arm_wrist_2_joint"/>
    <actuator name="arm_wrist_2_motor">
      <hardwareInterface>EffortJointInterface</hardwareInterface>
      <mechanicalReduction>1</mechanicalReduction>
    </actuator>
  </transmission>
  <transmission name="arm_wrist_3_trans">
    <type>transmission_interface/SimpleTransmission</type>
    <joint name="arm_wrist_3_joint"/>
    <actuator name="arm_wrist_3_motor">
      <hardwareInterface>EffortJointInterface</hardwareInterface>
      <mechanicalReduction>1</mechanicalReduction>
    </actuator>
  </transmission>
  <gazebo reference="universal_robot">
    <material>Gazebo/Blue</material>
  </gazebo>
  <joint name="arm_base_joint" type="fixed">
    <origin rpy="0.0 0.0 -0.785" xyz="0.13 0.53 0.01"/>
    <parent link="base_link"/>
    <child link="arm_base_link"/>
  </joint>
  <!-- Fleximon Cell -->
  <joint name="fleximon_cell_joint" type="fixed">
    <origin rpy="0 0 0" xyz="0 0 0"/>
    <parent link="base_link"/>
    <child link="fleximon_cell_link"/>
  </joint>
  <link name="fleximon_cell_link">
    <visual>
      <geometry>
        <mesh filename="package://iml_pick_in_bin_data/data/FlexiMon.dae"/>
      </geometry>
      <origin rpy="0.0 0.0 0.0" xyz="0.48 0.48 -0.81"/>
    </visual>
    <collision>
      <geometry>
        <mesh filename="package://iml_pick_in_bin_data/data/FlexiMon.dae"/>
      </geometry>
      <origin rpy="0.0 0.0 0.0" xyz="0.48 0.48 -0.81"/>
    </collision>
    <inertial>
      <mass value="100.0"/>
      <inertia ixx="1.0" ixy="0.0" ixz="0.0" iyy="1.0" iyz="0.0" izz="1.0"/>
      <origin rpy="0.0 0.0 0.0" xyz="0.0 0.0 0.0"/>
    </inertial>
  </link>
  <!-- Magazin -->
  <joint name="magazin_joint" type="fixed">
    <origin rpy="0 0 0" xyz="0 0 0"/>
    <parent link="base_link"/>
    <child link="magazin_link"/>
  </joint>
  <link name="magazin_link">
    <visual>
      <geometry>
        <mesh filename="package://iml_pick_in_bin_data/data/magazin.dae"/>
      </geometry>
      <origin rpy="0.0 0.0 0.0" xyz="0.39 -0.095 0.0"/>
    </visual>
    <collision>
      <geometry>
        <mesh filename="package://iml_pick_in_bin_data/data/magazin.dae"/>
      </geometry>
      <origin rpy="0.0 0.0 0.0" xyz="0.39 -0.095 0.0"/>
    </collision>
    <inertial>
      <mass value="100.0"/>
      <inertia ixx="1.0" ixy="0.0" ixz="0.0" iyy="1.0" iyz="0.0" izz="1.0"/>
      <origin rpy="0.0 0.0 0.0" xyz="0.0 0.0 0.0"/>
    </inertial>
  </link>
  <!-- AFAG gripper position of the mesa camera relative to base link -->
  <joint name="arm_afag_gripper_joint" type="fixed">
    <origin rpy="0 0 0" xyz="0 0 0"/>
    <parent link="arm_ee_link"/>
    <child link="arm_afag_gripper_link"/>
  </joint>
  <link name="arm_afag_gripper_link">
    <visual>
      <geometry>
        <mesh filename="package://iml_pick_in_bin_data/data/afag_gripper50.dae"/>
      </geometry>
      <origin rpy="-0.785 0.0 0" xyz="0 0 0"/>
      <!--origin rpy="0 0.0 1.57" xyz="0.069 -0.0315 -0.0315"/-->
      <!--origin rpy="0 -0.785 1.57" xyz="0.069 0.063 -0.0315"/-->
    </visual>
    <collision>
      <geometry>
        <mesh filename="package://iml_pick_in_bin_data/data/afag_gripper50.dae"/>
      </geometry>
      <origin rpy="0.0 0.0 0.0" xyz="0.0 0.0 0.0"/>
    </collision>
    <inertial>
      <mass value="100.0"/>
      <inertia ixx="1.0" ixy="0.0" ixz="0.0" iyy="1.0" iyz="0.0" izz="1.0"/>
      <origin rpy="0.0 0.0 0.0" xyz="0.0 0.0 0.0"/>
    </inertial>
  </link>
  <joint name="{arm_prefix}ee_joint" type="fixed">
    <origin rpy="0 0 0" xyz="0 0 0"/>
    <parent link="arm_ee_link"/>
    <child link="afag_gripper_link"/>
  </joint>
</robot>

